# question

- 使用 async await 会阻塞同步的线程 包括 ui 和用户交互吗？
- JS 的单线程和浏览器的多线程架构是怎样的关系 比如打开一个 tab 页 开启了几个进程 几个线程
- 并发 是指同一段时间内 两个独立的任务**交替运行** 看起来像是同时运行 按照在事件循环中的顺序 有序运行
- 单线程事件循环是并发的一种形式
- ES5 之前是事件循环队列 ES6 后 叫做任务队列。
- 事件循环和任务队列不是一个概念 任务队列是 promise 的异步特性 优先级高

#### 关于 setTimeout()何时会被加入回调队列

- 在定时器到达时间后，宿主环境会将回调函数加入到事件循环中 如果此时事件循环队列中的回调函数多，那 setTimeout 的回调函数就得等待 所以 setTimeout 的精度不是很高

#### JS 引擎和宿主环境的关系 事件循环

- JS 引擎运行在不同的环境中 每种环境都提供了一种机制 来处理程序中多个块的执行 且执行每个块的时候调用 JS 引擎 这种机制被称为事件循环。

#### 异步和并行

- 异步是关于现在和将来的时间间隙 事件循环把自身的工作分为一个个任务 并且按照顺序执行**不能对于共享内存并行访问和修改 通过分立线程中合作的事件循环 并行和顺序执行可以共存**
- 并行是关于能够同时发生的事情 进程和线层是并行最常见的工具 进程和线程能够独立运行 也可能同时运行 多个线程能够共享单个进程的内存。
- 结论 ： 并行线程的交替执行和异步事件的**交替调度** 其粒度完全不同

#### 回调存在的问题

- 代码难以阅读和维护
- 如果使用第三方库 那回调的调用次数 调用时机 回调函数否会被调用 回调函数的调用顺序 都会存在信任问题。

#### 如何检查一个对象是否是 promise 实例

#### 如何判断一个函数是否是 promise ? 已解决

#### promise 是怎样解决掉回调函数的缺点的

- 回调函数的缺点：

  不确定回调函数究竟

  - 1： 是否被执行
  - 2： 调用过早
  - 3： 调用过晚
  - 4： 调用次数过多或者调用次数太少
  - 5： 未能传递环境参数
  - 6：吐掉错误或者异常

- promise 的优点

  - 状态是唯一的 不是 fulfilled rejected 而且状态一旦发生该变 就固化了 不会再发生改变 之后的不当的改变状态的操作 会被忽视， 所以 promise**总是能保证回调函数在状态变更后执行一次**
  - 如果没有给 fulfilled（）传递任何参数，这个值是 undefined； 假如传递参数 只能传递一个参数，其他的多余的参数会被默默忽略 这是 promise 的保护机制。
  - promise 对于错误的处理行为

    - promise 构造器内同步的代码错误 会被当做异步错误处理 会被 promise 实例的 catch 捕获； 后续异步代码不会受到影响； 如果这个错误不用 catch 捕获 也不会影响后续异步代码的执行

      ```javascript
      当错误发生在构造器内
      let p = new Promise((resolve, reject) => {
        fn();                        从这个错误的地方开始 promise构造器内部的以下代码不会执行
        console.log("0000000000");
        resolve(100);
      });
      p.then(
        (res) => {
          console.log(res);
        },
        (error) => {
          console.log(error);          // 错误会在这里被打印
        }
      );

      setTimeout(() => {
        console.log("---------");     // 但是不会影响后续异步代码的执行
      }, 1000);

      ```

    - 在.then()的回调函数内部的发生的错误 如果没有被捕获，则 后续的异步代码会被影响； 如果被捕获则不会影响后续异步代码的执行

      ```javascript
      let p = new Promise((resolve, reject) => {
        resolve(100);
      });
      p.then(
        (res) => {
          fn(); // 错误发生
          console.log(res);
        },
        (error) => {
          console.log(error);
        }
      ).then(
        (res) => {
          console.log(res);
        },
        (rej) => {
          console.log(rej); // 这个错误被捕获 不会影响后续异步的代码的执行
        }
      );
      setTimeout(() => {
        console.log("---------");
      }, 1000);
      ```

  -
  -
  -

- 总结： promise 使异步编码更加清晰； 但是 promise 并没有完全摆脱回调 只是改变了传递回调的位置

#### promise.resolve()

- 能将任何非 promise 的代码转换为 promise 对象 ；
- 可以将任何不是 promise 对象但是有.thenable()方法的对象包装为 promise 对象
- 如果传入的是一个 promise 那返回的是一个 promise
  ```javascript
  let p = new Promise((resolve, reject) => {
    resolve(Promise.resolve("000")); //   Promise.resolve   Promise.reject 分别调用.then()不同的回调；
  });
  p.then((res) => {
    console.log(res);
  });
  ```

#### promise 有哪些缺点

- promise 链式调用中产生的错误容易被默默忽略掉
- 单一值
- 单决议 状态一旦变更 则不可更改
- 无法送外部取消一个 promise 的 pending 进程

#### .then( success,fail)

- 1: 即使没有在.then 的成功的回调函数为 null 这个 000 还是会被默认传递到下一个 promise 的成功回调的参数里面

```javascript
let p = new Promise((resolve, reject) => {
  resolve("000");
});
p.then(null).then((res) => console.log(res, "ppppp"));
```

#### .catch()

- 1: 能处理.catch 之前的 promise 链式调用中产生的错误 但是对于.catch 本身产生的 promise 的错误无法处理

#### 任何 promise 链式调用的最后一步，不管是啥，总是存在这未被查看的 promise 中出现未捕获错误的可能性

#### 处理未捕获错误的方法

- 将未被捕获的错误抛到全局

#### 在那种情况下 promise 会被自动忽略？？

#### `let p1 = Promise.race([]); p1的状态为pending`

#### `let p1 = Promise.all([]); 会立即执行p1成功的回调函数`

## 生成器

- 生成器可以 yield 一个 promise（ 暂停一个 await promise 内部代码的执行) ,用其完成其来回复这个生成器的运行，优化了 promise 的链式调用可能产生的回调地域**迭代器**可以自动执行这种模式
